[0m17:06:45  Running with dbt=1.7.14
Serving docs at 8080
To access from your browser, navigate to: http://localhost:8080



Press Ctrl+C to exit.
127.0.0.1 - - [21/May/2025 17:06:46] "GET / HTTP/1.1" 200 -
127.0.0.1 - - [21/May/2025 17:06:46] "GET /manifest.json?cb=1747847206299 HTTP/1.1" 200 -
127.0.0.1 - - [21/May/2025 17:06:46] "GET /catalog.json?cb=1747847206299 HTTP/1.1" 200 -
127.0.0.1 - - [21/May/2025 17:06:46] "GET / HTTP/1.1" 200 -
127.0.0.1 - - [21/May/2025 17:06:46] "GET / HTTP/1.1" 200 -
[32m2025-05-21 17:06:47 +0000[0m - dagster - [34mINFO[0m - Loaded environment variables from .env file: DBT_USER,DBT_PASS
Traceback (most recent call last):
  File "/home/blair/scr/dagster/venv/lib/python3.11/site-packages/sqlalchemy/engine/base.py", line 1963, in _exec_single_context
    self.dialect.do_execute(
  File "/home/blair/scr/dagster/venv/lib/python3.11/site-packages/sqlalchemy/engine/default.py", line 943, in do_execute
    cursor.execute(statement, parameters)
sqlite3.OperationalError: table secondary_indexes already exists

The above exception was the direct cause of the following exception:

Traceback (most recent call last):
  File "/home/blair/scr/dagster/venv/bin/dagster", line 8, in <module>
    sys.exit(main())
             ^^^^^^
  File "/home/blair/scr/dagster/venv/lib/python3.11/site-packages/dagster/_cli/__init__.py", line 50, in main
    cli(auto_envvar_prefix=ENV_PREFIX)
  File "/home/blair/scr/dagster/venv/lib/python3.11/site-packages/click/core.py", line 1161, in __call__
    return self.main(*args, **kwargs)
           ^^^^^^^^^^^^^^^^^^^^^^^^^^
  File "/home/blair/scr/dagster/venv/lib/python3.11/site-packages/click/core.py", line 1082, in main
    rv = self.invoke(ctx)
         ^^^^^^^^^^^^^^^^
  File "/home/blair/scr/dagster/venv/lib/python3.11/site-packages/click/core.py", line 1697, in invoke
    return _process_result(sub_ctx.command.invoke(sub_ctx))
                           ^^^^^^^^^^^^^^^^^^^^^^^^^^^^^^^
  File "/home/blair/scr/dagster/venv/lib/python3.11/site-packages/click/core.py", line 1443, in invoke
    return ctx.invoke(self.callback, **ctx.params)
           ^^^^^^^^^^^^^^^^^^^^^^^^^^^^^^^^^^^^^^^
  File "/home/blair/scr/dagster/venv/lib/python3.11/site-packages/click/core.py", line 788, in invoke
    return __callback(*args, **kwargs)
           ^^^^^^^^^^^^^^^^^^^^^^^^^^^
  File "/home/blair/scr/dagster/venv/lib/python3.11/site-packages/dagster/_cli/dev.py", line 164, in dev_command
    instance = stack.enter_context(
               ^^^^^^^^^^^^^^^^^^^^
  File "/usr/lib/python3.11/contextlib.py", line 505, in enter_context
    result = _enter(cm)
             ^^^^^^^^^^
  File "/usr/lib/python3.11/contextlib.py", line 137, in __enter__
    return next(self.gen)
           ^^^^^^^^^^^^^^
  File "/home/blair/scr/dagster/venv/lib/python3.11/site-packages/dagster/_cli/utils.py", line 107, in get_possibly_temporary_instance_for_cli
    with DagsterInstance.get() as instance:
         ^^^^^^^^^^^^^^^^^^^^^
  File "/home/blair/scr/dagster/venv/lib/python3.11/site-packages/dagster/_core/instance/__init__.py", line 600, in get
    return DagsterInstance.from_config(dagster_home_path)
           ^^^^^^^^^^^^^^^^^^^^^^^^^^^^^^^^^^^^^^^^^^^^^^
  File "/home/blair/scr/dagster/venv/lib/python3.11/site-packages/dagster/_core/instance/__init__.py", line 635, in from_config
    return DagsterInstance.from_ref(instance_ref)
           ^^^^^^^^^^^^^^^^^^^^^^^^^^^^^^^^^^^^^^
  File "/home/blair/scr/dagster/venv/lib/python3.11/site-packages/dagster/_core/instance/__init__.py", line 647, in from_ref
    unified_storage = instance_ref.storage
                      ^^^^^^^^^^^^^^^^^^^^
  File "/home/blair/scr/dagster/venv/lib/python3.11/site-packages/dagster/_core/instance/ref.py", line 502, in storage
    return self.storage_data.rehydrate(as_type=DagsterStorage) if self.storage_data else None
           ^^^^^^^^^^^^^^^^^^^^^^^^^^^^^^^^^^^^^^^^^^^^^^^^^^^
  File "/home/blair/scr/dagster/venv/lib/python3.11/site-packages/dagster/_serdes/config_class.py", line 118, in rehydrate
    return klass.from_config_value(self, check.not_none(result.value))
           ^^^^^^^^^^^^^^^^^^^^^^^^^^^^^^^^^^^^^^^^^^^^^^^^^^^^^^^^^^^
  File "/home/blair/scr/dagster/venv/lib/python3.11/site-packages/dagster/_core/storage/sqlite_storage.py", line 80, in from_config_value
    return DagsterSqliteStorage.from_local(inst_data=inst_data, **config_value)
           ^^^^^^^^^^^^^^^^^^^^^^^^^^^^^^^^^^^^^^^^^^^^^^^^^^^^^^^^^^^^^^^^^^^^
  File "/home/blair/scr/dagster/venv/lib/python3.11/site-packages/dagster/_core/storage/sqlite_storage.py", line 86, in from_local
    return cls(base_dir, inst_data=inst_data)
           ^^^^^^^^^^^^^^^^^^^^^^^^^^^^^^^^^^
  File "/home/blair/scr/dagster/venv/lib/python3.11/site-packages/dagster/_core/storage/sqlite_storage.py", line 62, in __init__
    self._run_storage = SqliteRunStorage.from_local(_runs_directory(base_dir))
                        ^^^^^^^^^^^^^^^^^^^^^^^^^^^^^^^^^^^^^^^^^^^^^^^^^^^^^^
  File "/home/blair/scr/dagster/venv/lib/python3.11/site-packages/dagster/_core/storage/runs/sqlite/sqlite_run_storage.py", line 112, in from_local
    RunStorageSqlMetadata.create_all(engine)
  File "/home/blair/scr/dagster/venv/lib/python3.11/site-packages/sqlalchemy/sql/schema.py", line 5924, in create_all
    bind._run_ddl_visitor(
  File "/home/blair/scr/dagster/venv/lib/python3.11/site-packages/sqlalchemy/engine/base.py", line 3248, in _run_ddl_visitor
    conn._run_ddl_visitor(visitorcallable, element, **kwargs)
  File "/home/blair/scr/dagster/venv/lib/python3.11/site-packages/sqlalchemy/engine/base.py", line 2455, in _run_ddl_visitor
    ).traverse_single(element)
      ^^^^^^^^^^^^^^^^^^^^^^^^
  File "/home/blair/scr/dagster/venv/lib/python3.11/site-packages/sqlalchemy/sql/visitors.py", line 664, in traverse_single
    return meth(obj, **kw)
           ^^^^^^^^^^^^^^^
  File "/home/blair/scr/dagster/venv/lib/python3.11/site-packages/sqlalchemy/sql/ddl.py", line 982, in visit_metadata
    self.traverse_single(
  File "/home/blair/scr/dagster/venv/lib/python3.11/site-packages/sqlalchemy/sql/visitors.py", line 664, in traverse_single
    return meth(obj, **kw)
           ^^^^^^^^^^^^^^^
  File "/home/blair/scr/dagster/venv/lib/python3.11/site-packages/sqlalchemy/sql/ddl.py", line 1020, in visit_table
    )._invoke_with(self.connection)
      ^^^^^^^^^^^^^^^^^^^^^^^^^^^^^
  File "/home/blair/scr/dagster/venv/lib/python3.11/site-packages/sqlalchemy/sql/ddl.py", line 321, in _invoke_with
    return bind.execute(self)
           ^^^^^^^^^^^^^^^^^^
  File "/home/blair/scr/dagster/venv/lib/python3.11/site-packages/sqlalchemy/engine/base.py", line 1415, in execute
    return meth(
           ^^^^^
  File "/home/blair/scr/dagster/venv/lib/python3.11/site-packages/sqlalchemy/sql/ddl.py", line 187, in _execute_on_connection
    return connection._execute_ddl(
           ^^^^^^^^^^^^^^^^^^^^^^^^
  File "/home/blair/scr/dagster/venv/lib/python3.11/site-packages/sqlalchemy/engine/base.py", line 1526, in _execute_ddl
    ret = self._execute_context(
          ^^^^^^^^^^^^^^^^^^^^^^
  File "/home/blair/scr/dagster/venv/lib/python3.11/site-packages/sqlalchemy/engine/base.py", line 1842, in _execute_context
    return self._exec_single_context(
           ^^^^^^^^^^^^^^^^^^^^^^^^^^
  File "/home/blair/scr/dagster/venv/lib/python3.11/site-packages/sqlalchemy/engine/base.py", line 1982, in _exec_single_context
    self._handle_dbapi_exception(
  File "/home/blair/scr/dagster/venv/lib/python3.11/site-packages/sqlalchemy/engine/base.py", line 2351, in _handle_dbapi_exception
    raise sqlalchemy_exception.with_traceback(exc_info[2]) from e
  File "/home/blair/scr/dagster/venv/lib/python3.11/site-packages/sqlalchemy/engine/base.py", line 1963, in _exec_single_context
    self.dialect.do_execute(
  File "/home/blair/scr/dagster/venv/lib/python3.11/site-packages/sqlalchemy/engine/default.py", line 943, in do_execute
    cursor.execute(statement, parameters)
sqlalchemy.exc.OperationalError: (sqlite3.OperationalError) table secondary_indexes already exists
[SQL: 
CREATE TABLE secondary_indexes (
	id INTEGER NOT NULL, 
	name VARCHAR(512), 
	create_timestamp DATETIME DEFAULT CURRENT_TIMESTAMP, 
	migration_completed DATETIME, 
	PRIMARY KEY (id), 
	UNIQUE (name)
)

]
(Background on this error at: https://sqlalche.me/e/20/e3q8)

  Telemetry:

  As an open-source project, we collect usage statistics to inform development priorities. For more
  information, read https://docs.dagster.io/about/telemetry.

  We will not see or store any data that is processed by your code.

  To opt-out, add the following to $DAGSTER_HOME/dagster.yaml, creating that file if necessary:

    telemetry:
      enabled: false


  Welcome to Dagster!

  If you have any questions or would like to engage with the Dagster team, please join us on Slack
  (https://bit.ly/39dvSsF).

Usage: dagster-daemon run [OPTIONS]
Try 'dagster-daemon run --help' for help.

Error: No arguments given and no [tool.dagster] block in pyproject.toml found.
nohup: ignoring input
[32m2025-05-21 19:37:20 +0000[0m - dagster.code_server - [34mERROR[0m - [31mError while importing code[0m
Traceback (most recent call last):
  File "/home/blair/scr/dagster/venv/lib/python3.11/site-packages/dagster/_core/code_pointer.py", line 138, in load_python_module
    return importlib.import_module(module_name)
           ^^^^^^^^^^^^^^^^^^^^^^^^^^^^^^^^^^^^
  File "/usr/lib/python3.11/importlib/__init__.py", line 126, in import_module
    return _bootstrap._gcd_import(name[level:], package, level)
           ^^^^^^^^^^^^^^^^^^^^^^^^^^^^^^^^^^^^^^^^^^^^^^^^^^^^
  File "<frozen importlib._bootstrap>", line 1206, in _gcd_import
  File "<frozen importlib._bootstrap>", line 1178, in _find_and_load
  File "<frozen importlib._bootstrap>", line 1128, in _find_and_load_unlocked
  File "<frozen importlib._bootstrap>", line 241, in _call_with_frames_removed
  File "<frozen importlib._bootstrap>", line 1206, in _gcd_import
  File "<frozen importlib._bootstrap>", line 1178, in _find_and_load
  File "<frozen importlib._bootstrap>", line 1142, in _find_and_load_unlocked
ModuleNotFoundError: No module named 'analytics'

The above exception was the direct cause of the following exception:

Traceback (most recent call last):
  File "/home/blair/scr/dagster/venv/lib/python3.11/site-packages/dagster/_grpc/server.py", line 435, in __init__
    self._loaded_repositories: Optional[LoadedRepositories] = LoadedRepositories(
                                                              ^^^^^^^^^^^^^^^^^^^
  File "/home/blair/scr/dagster/venv/lib/python3.11/site-packages/dagster/_grpc/server.py", line 268, in __init__
    loadable_targets = get_loadable_targets(
                       ^^^^^^^^^^^^^^^^^^^^^
  File "/home/blair/scr/dagster/venv/lib/python3.11/site-packages/dagster/_grpc/utils.py", line 51, in get_loadable_targets
    else loadable_targets_from_python_module(module_name, working_directory)
         ^^^^^^^^^^^^^^^^^^^^^^^^^^^^^^^^^^^^^^^^^^^^^^^^^^^^^^^^^^^^^^^^^^^
  File "/home/blair/scr/dagster/venv/lib/python3.11/site-packages/dagster/_core/workspace/autodiscovery.py", line 33, in loadable_targets_from_python_module
    module = load_python_module(
             ^^^^^^^^^^^^^^^^^^^
  File "/home/blair/scr/dagster/venv/lib/python3.11/site-packages/dagster/_core/code_pointer.py", line 143, in load_python_module
    raise DagsterImportError(
dagster._core.errors.DagsterImportError: Encountered ImportError: `No module named 'analytics'` while importing module analytics.definitions. Local modules were resolved using the working directory `/home/blair/scr/dagster/analytics`. If another working directory should be used, please explicitly specify the appropriate path using the `-d` or `--working-directory` for CLI based targets or the `working_directory` configuration option for workspace targets. 
/home/blair/scr/dagster/venv/lib/python3.11/site-packages/dagster/_core/workspace/context.py:835: UserWarning: Error loading repository location analytics:dagster._core.errors.DagsterImportError: Encountered ImportError: `No module named 'analytics'` while importing module analytics.definitions. Local modules were resolved using the working directory `/home/blair/scr/dagster/analytics`. If another working directory should be used, please explicitly specify the appropriate path using the `-d` or `--working-directory` for CLI based targets or the `working_directory` configuration option for workspace targets. 

Stack Trace:
  File "/home/blair/scr/dagster/venv/lib/python3.11/site-packages/dagster/_grpc/server.py", line 435, in __init__
    self._loaded_repositories: Optional[LoadedRepositories] = LoadedRepositories(
                                                              ^^^^^^^^^^^^^^^^^^^
  File "/home/blair/scr/dagster/venv/lib/python3.11/site-packages/dagster/_grpc/server.py", line 268, in __init__
    loadable_targets = get_loadable_targets(
                       ^^^^^^^^^^^^^^^^^^^^^
  File "/home/blair/scr/dagster/venv/lib/python3.11/site-packages/dagster/_grpc/utils.py", line 51, in get_loadable_targets
    else loadable_targets_from_python_module(module_name, working_directory)
         ^^^^^^^^^^^^^^^^^^^^^^^^^^^^^^^^^^^^^^^^^^^^^^^^^^^^^^^^^^^^^^^^^^^
  File "/home/blair/scr/dagster/venv/lib/python3.11/site-packages/dagster/_core/workspace/autodiscovery.py", line 33, in loadable_targets_from_python_module
    module = load_python_module(
             ^^^^^^^^^^^^^^^^^^^
  File "/home/blair/scr/dagster/venv/lib/python3.11/site-packages/dagster/_core/code_pointer.py", line 143, in load_python_module
    raise DagsterImportError(

The above exception was caused by the following exception:
ModuleNotFoundError: No module named 'analytics'

Stack Trace:
  File "/home/blair/scr/dagster/venv/lib/python3.11/site-packages/dagster/_core/code_pointer.py", line 138, in load_python_module
    return importlib.import_module(module_name)
           ^^^^^^^^^^^^^^^^^^^^^^^^^^^^^^^^^^^^
  File "/usr/lib/python3.11/importlib/__init__.py", line 126, in import_module
    return _bootstrap._gcd_import(name[level:], package, level)
           ^^^^^^^^^^^^^^^^^^^^^^^^^^^^^^^^^^^^^^^^^^^^^^^^^^^^
  File "<frozen importlib._bootstrap>", line 1206, in _gcd_import
  File "<frozen importlib._bootstrap>", line 1178, in _find_and_load
  File "<frozen importlib._bootstrap>", line 1128, in _find_and_load_unlocked
  File "<frozen importlib._bootstrap>", line 241, in _call_with_frames_removed
  File "<frozen importlib._bootstrap>", line 1206, in _gcd_import
  File "<frozen importlib._bootstrap>", line 1178, in _find_and_load
  File "<frozen importlib._bootstrap>", line 1142, in _find_and_load_unlocked

  warnings.warn(
[32m2025-05-21 19:37:20 +0000[0m - dagster.daemon - [34mINFO[0m - Instance is configured with the following daemons: ['AssetDaemon', 'BackfillDaemon', 'QueuedRunCoordinatorDaemon', 'SchedulerDaemon', 'SensorDaemon']
[32m2025-05-21 19:37:20 +0000[0m - dagster.daemon.QueuedRunCoordinatorDaemon - [34mINFO[0m - Priority sorting and checking tag concurrency limits for queued runs.
[32m2025-05-21 19:37:20 +0000[0m - dagster.daemon.QueuedRunCoordinatorDaemon - [34mERROR[0m - [31mCaught an error dequeuing run 2d21f9dc-791d-457a-bef5-f32226a26395[0m
Traceback (most recent call last):
  File "/home/blair/scr/dagster/venv/lib/python3.11/site-packages/dagster/_daemon/run_coordinator/queued_run_coordinator_daemon.py", line 397, in _dequeue_run
    instance.run_launcher.launch_run(LaunchRunContext(dagster_run=run, workspace=workspace))
  File "/home/blair/scr/dagster/venv/lib/python3.11/site-packages/dagster/_core/launcher/default_run_launcher.py", line 110, in launch_run
    code_location = context.workspace.get_code_location(
                    ^^^^^^^^^^^^^^^^^^^^^^^^^^^^^^^^^^^^
  File "/home/blair/scr/dagster/venv/lib/python3.11/site-packages/dagster/_core/workspace/context.py", line 192, in get_code_location
    raise DagsterCodeLocationLoadError(
dagster._core.errors.DagsterCodeLocationLoadError: Failure loading analytics: dagster._core.errors.DagsterImportError: Encountered ImportError: `No module named 'analytics'` while importing module analytics.definitions. Local modules were resolved using the working directory `/home/blair/scr/dagster/analytics`. If another working directory should be used, please explicitly specify the appropriate path using the `-d` or `--working-directory` for CLI based targets or the `working_directory` configuration option for workspace targets. 

Stack Trace:
  File "/home/blair/scr/dagster/venv/lib/python3.11/site-packages/dagster/_grpc/server.py", line 435, in __init__
    self._loaded_repositories: Optional[LoadedRepositories] = LoadedRepositories(
                                                              ^^^^^^^^^^^^^^^^^^^
  File "/home/blair/scr/dagster/venv/lib/python3.11/site-packages/dagster/_grpc/server.py", line 268, in __init__
    loadable_targets = get_loadable_targets(
                       ^^^^^^^^^^^^^^^^^^^^^
  File "/home/blair/scr/dagster/venv/lib/python3.11/site-packages/dagster/_grpc/utils.py", line 51, in get_loadable_targets
    else loadable_targets_from_python_module(module_name, working_directory)
         ^^^^^^^^^^^^^^^^^^^^^^^^^^^^^^^^^^^^^^^^^^^^^^^^^^^^^^^^^^^^^^^^^^^
  File "/home/blair/scr/dagster/venv/lib/python3.11/site-packages/dagster/_core/workspace/autodiscovery.py", line 33, in loadable_targets_from_python_module
    module = load_python_module(
             ^^^^^^^^^^^^^^^^^^^
  File "/home/blair/scr/dagster/venv/lib/python3.11/site-packages/dagster/_core/code_pointer.py", line 143, in load_python_module
    raise DagsterImportError(

The above exception was caused by the following exception:
ModuleNotFoundError: No module named 'analytics'

Stack Trace:
  File "/home/blair/scr/dagster/venv/lib/python3.11/site-packages/dagster/_core/code_pointer.py", line 138, in load_python_module
    return importlib.import_module(module_name)
           ^^^^^^^^^^^^^^^^^^^^^^^^^^^^^^^^^^^^
  File "/usr/lib/python3.11/importlib/__init__.py", line 126, in import_module
    return _bootstrap._gcd_import(name[level:], package, level)
           ^^^^^^^^^^^^^^^^^^^^^^^^^^^^^^^^^^^^^^^^^^^^^^^^^^^^
  File "<frozen importlib._bootstrap>", line 1206, in _gcd_import
  File "<frozen importlib._bootstrap>", line 1178, in _find_and_load
  File "<frozen importlib._bootstrap>", line 1128, in _find_and_load_unlocked
  File "<frozen importlib._bootstrap>", line 241, in _call_with_frames_removed
  File "<frozen importlib._bootstrap>", line 1206, in _gcd_import
  File "<frozen importlib._bootstrap>", line 1178, in _find_and_load
  File "<frozen importlib._bootstrap>", line 1142, in _find_and_load_unlocked

[32m2025-05-21 19:38:21 +0000[0m - dagster.code_server - [34mERROR[0m - [31mError while importing code[0m
Traceback (most recent call last):
  File "/home/blair/scr/dagster/venv/lib/python3.11/site-packages/dagster/_core/code_pointer.py", line 138, in load_python_module
    return importlib.import_module(module_name)
           ^^^^^^^^^^^^^^^^^^^^^^^^^^^^^^^^^^^^
  File "/usr/lib/python3.11/importlib/__init__.py", line 126, in import_module
    return _bootstrap._gcd_import(name[level:], package, level)
           ^^^^^^^^^^^^^^^^^^^^^^^^^^^^^^^^^^^^^^^^^^^^^^^^^^^^
  File "<frozen importlib._bootstrap>", line 1206, in _gcd_import
  File "<frozen importlib._bootstrap>", line 1178, in _find_and_load
  File "<frozen importlib._bootstrap>", line 1128, in _find_and_load_unlocked
  File "<frozen importlib._bootstrap>", line 241, in _call_with_frames_removed
  File "<frozen importlib._bootstrap>", line 1206, in _gcd_import
  File "<frozen importlib._bootstrap>", line 1178, in _find_and_load
  File "<frozen importlib._bootstrap>", line 1142, in _find_and_load_unlocked
ModuleNotFoundError: No module named 'analytics'

The above exception was the direct cause of the following exception:

Traceback (most recent call last):
  File "/home/blair/scr/dagster/venv/lib/python3.11/site-packages/dagster/_grpc/server.py", line 435, in __init__
    self._loaded_repositories: Optional[LoadedRepositories] = LoadedRepositories(
                                                              ^^^^^^^^^^^^^^^^^^^
  File "/home/blair/scr/dagster/venv/lib/python3.11/site-packages/dagster/_grpc/server.py", line 268, in __init__
    loadable_targets = get_loadable_targets(
                       ^^^^^^^^^^^^^^^^^^^^^
  File "/home/blair/scr/dagster/venv/lib/python3.11/site-packages/dagster/_grpc/utils.py", line 51, in get_loadable_targets
    else loadable_targets_from_python_module(module_name, working_directory)
         ^^^^^^^^^^^^^^^^^^^^^^^^^^^^^^^^^^^^^^^^^^^^^^^^^^^^^^^^^^^^^^^^^^^
  File "/home/blair/scr/dagster/venv/lib/python3.11/site-packages/dagster/_core/workspace/autodiscovery.py", line 33, in loadable_targets_from_python_module
    module = load_python_module(
             ^^^^^^^^^^^^^^^^^^^
  File "/home/blair/scr/dagster/venv/lib/python3.11/site-packages/dagster/_core/code_pointer.py", line 143, in load_python_module
    raise DagsterImportError(
dagster._core.errors.DagsterImportError: Encountered ImportError: `No module named 'analytics'` while importing module analytics.definitions. Local modules were resolved using the working directory `/home/blair/scr/dagster/analytics`. If another working directory should be used, please explicitly specify the appropriate path using the `-d` or `--working-directory` for CLI based targets or the `working_directory` configuration option for workspace targets. 
[32m2025-05-21 19:38:21 +0000[0m - dagster - [34mWARNING[0m - /home/blair/scr/dagster/venv/lib/python3.11/site-packages/dagster/_core/workspace/context.py:835: UserWarning: Error loading repository location analytics:dagster._core.errors.DagsterImportError: Encountered ImportError: `No module named 'analytics'` while importing module analytics.definitions. Local modules were resolved using the working directory `/home/blair/scr/dagster/analytics`. If another working directory should be used, please explicitly specify the appropriate path using the `-d` or `--working-directory` for CLI based targets or the `working_directory` configuration option for workspace targets. 

Stack Trace:
  File "/home/blair/scr/dagster/venv/lib/python3.11/site-packages/dagster/_grpc/server.py", line 435, in __init__
    self._loaded_repositories: Optional[LoadedRepositories] = LoadedRepositories(
                                                              ^^^^^^^^^^^^^^^^^^^
  File "/home/blair/scr/dagster/venv/lib/python3.11/site-packages/dagster/_grpc/server.py", line 268, in __init__
    loadable_targets = get_loadable_targets(
                       ^^^^^^^^^^^^^^^^^^^^^
  File "/home/blair/scr/dagster/venv/lib/python3.11/site-packages/dagster/_grpc/utils.py", line 51, in get_loadable_targets
    else loadable_targets_from_python_module(module_name, working_directory)
         ^^^^^^^^^^^^^^^^^^^^^^^^^^^^^^^^^^^^^^^^^^^^^^^^^^^^^^^^^^^^^^^^^^^
  File "/home/blair/scr/dagster/venv/lib/python3.11/site-packages/dagster/_core/workspace/autodiscovery.py", line 33, in loadable_targets_from_python_module
    module = load_python_module(
             ^^^^^^^^^^^^^^^^^^^
  File "/home/blair/scr/dagster/venv/lib/python3.11/site-packages/dagster/_core/code_pointer.py", line 143, in load_python_module
    raise DagsterImportError(

The above exception was caused by the following exception:
ModuleNotFoundError: No module named 'analytics'

Stack Trace:
  File "/home/blair/scr/dagster/venv/lib/python3.11/site-packages/dagster/_core/code_pointer.py", line 138, in load_python_module
    return importlib.import_module(module_name)
           ^^^^^^^^^^^^^^^^^^^^^^^^^^^^^^^^^^^^
  File "/usr/lib/python3.11/importlib/__init__.py", line 126, in import_module
    return _bootstrap._gcd_import(name[level:], package, level)
           ^^^^^^^^^^^^^^^^^^^^^^^^^^^^^^^^^^^^^^^^^^^^^^^^^^^^
  File "<frozen importlib._bootstrap>", line 1206, in _gcd_import
  File "<frozen importlib._bootstrap>", line 1178, in _find_and_load
  File "<frozen importlib._bootstrap>", line 1128, in _find_and_load_unlocked
  File "<frozen importlib._bootstrap>", line 241, in _call_with_frames_removed
  File "<frozen importlib._bootstrap>", line 1206, in _gcd_import
  File "<frozen importlib._bootstrap>", line 1178, in _find_and_load
  File "<frozen importlib._bootstrap>", line 1142, in _find_and_load_unlocked

  warnings.warn(

[32m2025-05-21 19:39:08 +0000[0m - dagster.daemon - [34mINFO[0m - Received interrupt, shutting down daemon threads...
[32m2025-05-21 19:39:08 +0000[0m - dagster.daemon - [34mINFO[0m - Daemon threads shut down.
