[0m17:23:46.239923 [debug] [MainThread]: Sending event: {'category': 'dbt', 'action': 'invocation', 'label': 'start', 'context': [<snowplow_tracker.self_describing_json.SelfDescribingJson object at 0x7ffedb8ec210>, <snowplow_tracker.self_describing_json.SelfDescribingJson object at 0x7ffedb8ec190>, <snowplow_tracker.self_describing_json.SelfDescribingJson object at 0x7ffedbabba50>]}


============================== 17:23:46.243391 | 23e3759b-c315-44dd-9808-e0893b2d4404 ==============================
[0m17:23:46.243391 [info ] [MainThread]: Running with dbt=1.9.4
[0m17:23:46.244027 [debug] [MainThread]: running dbt with arguments {'printer_width': '80', 'indirect_selection': 'eager', 'log_cache_events': 'False', 'write_json': 'True', 'partial_parse': 'True', 'cache_selected_only': 'False', 'warn_error': 'None', 'debug': 'False', 'fail_fast': 'False', 'log_path': 'logs', 'version_check': 'True', 'profiles_dir': '/home/blair/.dbt', 'use_colors': 'True', 'use_experimental_parser': 'False', 'empty': 'None', 'quiet': 'False', 'no_print': 'None', 'warn_error_options': 'WarnErrorOptions(include=[], exclude=[])', 'introspect': 'True', 'invocation_command': 'dbt docs generate', 'static_parser': 'True', 'target_path': 'None', 'log_format': 'default', 'send_anonymous_usage_stats': 'True'}
[0m17:23:46.244531 [error] [MainThread]: Encountered an error:
Runtime Error
  No dbt_project.yml found at expected path /home/blair/scr/dbt/dbt_project.yml
  Verify that each entry within packages.yml (and their transitive dependencies) contains a file named dbt_project.yml
  
[0m17:23:46.245504 [debug] [MainThread]: Resource report: {"command_name": "generate", "command_success": false, "command_wall_clock_time": 0.059877608, "process_in_blocks": "0", "process_kernel_time": 0.099989, "process_mem_max_rss": "95680", "process_out_blocks": "32", "process_user_time": 1.419857}
[0m17:23:46.245990 [debug] [MainThread]: Command `dbt docs generate` failed at 17:23:46.245883 after 0.06 seconds
[0m17:23:46.246393 [debug] [MainThread]: Sending event: {'category': 'dbt', 'action': 'invocation', 'label': 'end', 'context': [<snowplow_tracker.self_describing_json.SelfDescribingJson object at 0x7ffedb70a8d0>, <snowplow_tracker.self_describing_json.SelfDescribingJson object at 0x7ffedb70af90>, <snowplow_tracker.self_describing_json.SelfDescribingJson object at 0x7ffedb8b3dd0>]}
[0m17:23:46.246805 [debug] [MainThread]: Flushing usage events
[0m17:23:46.576813 [debug] [MainThread]: An error was encountered while trying to flush usage events
[0m17:23:48.457347 [debug] [MainThread]: Sending event: {'category': 'dbt', 'action': 'invocation', 'label': 'start', 'context': [<snowplow_tracker.self_describing_json.SelfDescribingJson object at 0x7ffeea9fa2d0>, <snowplow_tracker.self_describing_json.SelfDescribingJson object at 0x7ffeeaca8610>, <snowplow_tracker.self_describing_json.SelfDescribingJson object at 0x7ffeeacaae50>]}


============================== 17:23:48.460796 | f2304d85-140a-4e31-b226-2b8ef9955f76 ==============================
[0m17:23:48.460796 [info ] [MainThread]: Running with dbt=1.9.4
[0m17:23:48.461515 [debug] [MainThread]: running dbt with arguments {'printer_width': '80', 'indirect_selection': 'eager', 'write_json': 'True', 'log_cache_events': 'False', 'partial_parse': 'True', 'cache_selected_only': 'False', 'warn_error': 'None', 'fail_fast': 'False', 'debug': 'False', 'log_path': 'logs', 'profiles_dir': '/home/blair/.dbt', 'version_check': 'True', 'use_colors': 'True', 'use_experimental_parser': 'False', 'empty': 'None', 'quiet': 'False', 'no_print': 'None', 'log_format': 'default', 'introspect': 'True', 'invocation_command': 'dbt docs serve', 'static_parser': 'True', 'target_path': 'None', 'warn_error_options': 'WarnErrorOptions(include=[], exclude=[])', 'send_anonymous_usage_stats': 'True'}
[0m17:23:48.462041 [error] [MainThread]: Encountered an error:
Runtime Error
  No dbt_project.yml found at expected path /home/blair/scr/dbt/dbt_project.yml
  Verify that each entry within packages.yml (and their transitive dependencies) contains a file named dbt_project.yml
  
[0m17:23:48.463020 [debug] [MainThread]: Resource report: {"command_name": "serve", "command_success": false, "command_wall_clock_time": 0.05884111, "process_in_blocks": "0", "process_kernel_time": 0.091434, "process_mem_max_rss": "95584", "process_out_blocks": "0", "process_user_time": 1.447044}
[0m17:23:48.463510 [debug] [MainThread]: Command `dbt docs serve` failed at 17:23:48.463400 after 0.06 seconds
[0m17:23:48.463913 [debug] [MainThread]: Sending event: {'category': 'dbt', 'action': 'invocation', 'label': 'end', 'context': [<snowplow_tracker.self_describing_json.SelfDescribingJson object at 0x7ffeeaa05850>, <snowplow_tracker.self_describing_json.SelfDescribingJson object at 0x7ffeeaa05810>, <snowplow_tracker.self_describing_json.SelfDescribingJson object at 0x7ffeeaba3e50>]}
[0m17:23:48.464330 [debug] [MainThread]: Flushing usage events
[0m17:23:48.823497 [debug] [MainThread]: An error was encountered while trying to flush usage events
